<?xml version="1.0"?>
<robot xmlns:xacro="http://www.ros.org/wiki/xacro" name="dabakama_ai">

    <xacro:include filename="/root/ros_ws/src/car/urdf/materials.xacro"/>
    <xacro:include filename="/root/ros_ws/src/car/urdf/common_properties.xacro"/>
    <xacro:include filename="/root/ros_ws/src/car/urdf/dabakama_ai_gazebo.xacro"/>
    <link name="base_footprint" />

    <link name="base_link">
        <visual>
            <geometry>
                <box size="0.8 0.4 0.2" />
            </geometry>
            <origin xyz="0 0 0.1" rpy="0 0 0" />
            <material name="blue" />
        </visual>
        <collision>
            <geometry>
                <box size="0.8 0.4 0.2" />
            </geometry>
            <origin xyz="0 0 0.1" rpy="0 0 0" />
        </collision>
        <xacro:box_inertia m="0.5" x="0.8" y="0.4" z="0.2" o_xyz="0 0 0.1" o_rpy="0 0 0"/>
    </link>

    <link name="back_right_wheel_link">
        <visual>
            <geometry>
                <cylinder radius="0.1" length="0.05" />
            </geometry>
            <origin xyz="0 0 0" rpy="1.57 0 0" />
            <material name="purple" />
        </visual>
        <collision>
            <geometry>
                <cylinder radius="0.1" length="0.05" />
            </geometry>
            <origin xyz="0 0 0" rpy="1.57 0 0" />
        </collision>
        <xacro:cylinder_inertia m="0.5" r="0.1" l="0.05" o_xyz="0 0 0" o_rpy="1.57 0 0"/>
    </link>

    <link name="back_left_wheel_link">
        <visual>
            <geometry>
                <cylinder radius="0.1" length="0.05" />
            </geometry>
            <origin xyz="0 0 0" rpy="1.57 0 0" />
            <material name="grey" />
        </visual>
        <collision>
            <geometry>
                <cylinder radius="0.1" length="0.05" />
            </geometry>
            <origin xyz="0 0 0" rpy="1.57 0 0" />
        </collision>
        <xacro:cylinder_inertia m="0.5" r="0.1" l="0.05" o_xyz="0 0 0" o_rpy="1.57 0 0"/>
    </link>

     <link name="left_caster_wheel_link">
        <visual>
            <geometry>
                <sphere radius="0.05" />
            </geometry>
            <origin xyz="0 0 -0.035 " rpy="0 0 0" />
            <material name="grey" />
        </visual>
        <collision>
            <geometry>
                <sphere radius="0.05" />
            </geometry>
            <origin xyz="0 0 -0.035" rpy="0 0 0" />
        </collision>
        <xacro:sphere_inertia m="0.5" r="0.05"
                              o_xyz="0 0 -0.035 " o_rpy="0 0 0" />
    </link>

     <link name="right_caster_wheel_link">
        <visual>
            <geometry>
                <sphere radius="0.05" />
            </geometry>
            <origin xyz="0 0 -0.035 " rpy="0 0 0" />
            <material name="red" />
        </visual>
        <collision>
            <geometry>
                <sphere radius="0.05" />
            </geometry>
            <origin xyz="0 0 -0.035 " rpy="0 0 0" />
        </collision>
        <xacro:sphere_inertia m="0.5" r="0.05"
                              o_xyz="0 0 -0.035 " o_rpy="0 0 0" />
    </link>

    <link name="lidar">
        <visual>
            <geometry>
                <cylinder radius="0.02" length="0.05"/>
            </geometry>
            <material name="grey"/>
            <origin xyz="0.01 0 0" rpy="0 1.57 0"/>
        </visual>
        <collision>
            <geometry>
                <cylinder radius="0.02" length="0.05"/>
            </geometry>
            <origin xyz="0.01 0 0" rpy="0 0 0"/>
        </collision>
        <xacro:sphere_inertia m="0.5" r="0.02"
                              o_xyz="0.01 0 0" o_rpy="0 1.57 0"/>
    </link>



    

   <!-- Joints Back-->

    <joint name="base_joint" type="fixed">
        <parent link="base_footprint" />
        <child link="base_link" />
        <origin xyz="0 0 0.1" rpy="0 0 0"/>
    </joint>

    <joint name="base_bottom_right_wheel_joint" type="continuous">
        <parent link="base_link" />
        <child link="back_right_wheel_link" />
        <origin xyz="-0.25 -0.225 0" rpy="0 0 0" />
        <axis xyz="0 1 0" />
    </joint>

    <joint name="base_bottom_left_wheel_joint" type="continuous">
        <parent link="base_link" />
        <child link="back_left_wheel_link" />
        <origin xyz="-0.25 0.225 0" rpy="0 0 0" />
        <axis xyz="0 1 0" />
    </joint>


    <joint name="base_left_caster_wheel_joint" type="fixed">
        <parent link="base_link" />
        <child link="left_caster_wheel_link" />
        <origin xyz="0.25 0.125 0" rpy="0 0 0" />
        <axis xyz="0 1 0" />
    </joint>
    <joint name="base_right_caster_wheel_joint" type="fixed">
        <parent link="base_link" />
        <child link="right_caster_wheel_link" />
        <origin xyz="0.25 -0.125 0" rpy="0 0 0" />
        <axis xyz="0 1 0" />
    </joint>

    <joint name="ultrasonic_sensor_joint" type="fixed">
        <parent link="base_link"/>
        <child link="lidar"/>
        <origin xyz="0.4 0 0.3" rpy="0 0 0"/>
</joint>


    

</robot>